
2019-12-16 20:34:44,551 INFO: errors [in app.py:507]
2019-12-16 20:35:12,183 INFO: errors [in app.py:507]
2019-12-16 20:35:36,490 INFO: errors [in app.py:507]
2019-12-16 20:37:41,277 INFO: errors [in app.py:507]
2019-12-23 08:52:13,751 INFO: errors [in app.py:586]
2019-12-23 08:52:22,624 ERROR: Exception on /venues/create [GET] [in /Library/Frameworks/Python.framework/Versions/3.7/lib/python3.7/site-packages/flask/app.py:1891]
Traceback (most recent call last):
  File "/Library/Frameworks/Python.framework/Versions/3.7/lib/python3.7/site-packages/flask/app.py", line 2446, in wsgi_app
    response = self.full_dispatch_request()
  File "/Library/Frameworks/Python.framework/Versions/3.7/lib/python3.7/site-packages/flask/app.py", line 1951, in full_dispatch_request
    rv = self.handle_user_exception(e)
  File "/Library/Frameworks/Python.framework/Versions/3.7/lib/python3.7/site-packages/flask/app.py", line 1820, in handle_user_exception
    reraise(exc_type, exc_value, tb)
  File "/Library/Frameworks/Python.framework/Versions/3.7/lib/python3.7/site-packages/flask/_compat.py", line 39, in reraise
    raise value
  File "/Library/Frameworks/Python.framework/Versions/3.7/lib/python3.7/site-packages/flask/app.py", line 1949, in full_dispatch_request
    rv = self.dispatch_request()
  File "/Library/Frameworks/Python.framework/Versions/3.7/lib/python3.7/site-packages/flask/app.py", line 1935, in dispatch_request
    return self.view_functions[rule.endpoint](**req.view_args)
  File "app.py", line 189, in create_venue_form
    form = VenueForm()
  File "/Library/Frameworks/Python.framework/Versions/3.7/lib/python3.7/site-packages/wtforms/form.py", line 212, in __call__
    return type.__call__(cls, *args, **kwargs)
  File "/Library/Frameworks/Python.framework/Versions/3.7/lib/python3.7/site-packages/flask_wtf/form.py", line 158, in __init__
    super(Form, self).__init__(*args, **kwargs)
  File "/Library/Frameworks/Python.framework/Versions/3.7/lib/python3.7/site-packages/flask_wtf/form.py", line 88, in __init__
    super(FlaskForm, self).__init__(formdata=formdata, **kwargs)
  File "/Library/Frameworks/Python.framework/Versions/3.7/lib/python3.7/site-packages/wtforms/form.py", line 278, in __init__
    self.process(formdata, obj, data=data, **kwargs)
  File "/Library/Frameworks/Python.framework/Versions/3.7/lib/python3.7/site-packages/wtforms/form.py", line 132, in process
    field.process(formdata)
  File "/Library/Frameworks/Python.framework/Versions/3.7/lib/python3.7/site-packages/wtforms/csrf/core.py", line 43, in process
    self.current_token = self.csrf_impl.generate_csrf_token(self)
  File "/Library/Frameworks/Python.framework/Versions/3.7/lib/python3.7/site-packages/flask_wtf/csrf.py", line 134, in generate_csrf_token
    token_key=self.meta.csrf_field_name
  File "/Library/Frameworks/Python.framework/Versions/3.7/lib/python3.7/site-packages/flask_wtf/csrf.py", line 35, in generate_csrf
    message='A secret key is required to use CSRF.'
  File "/Library/Frameworks/Python.framework/Versions/3.7/lib/python3.7/site-packages/flask_wtf/csrf.py", line 121, in _get_config
    raise KeyError(message)
KeyError: 'A secret key is required to use CSRF.'
2019-12-23 08:53:12,608 ERROR: Exception on /venues/create [GET] [in /Library/Frameworks/Python.framework/Versions/3.7/lib/python3.7/site-packages/flask/app.py:1891]
Traceback (most recent call last):
  File "/Library/Frameworks/Python.framework/Versions/3.7/lib/python3.7/site-packages/flask/app.py", line 2446, in wsgi_app
    response = self.full_dispatch_request()
  File "/Library/Frameworks/Python.framework/Versions/3.7/lib/python3.7/site-packages/flask/app.py", line 1951, in full_dispatch_request
    rv = self.handle_user_exception(e)
  File "/Library/Frameworks/Python.framework/Versions/3.7/lib/python3.7/site-packages/flask/app.py", line 1820, in handle_user_exception
    reraise(exc_type, exc_value, tb)
  File "/Library/Frameworks/Python.framework/Versions/3.7/lib/python3.7/site-packages/flask/_compat.py", line 39, in reraise
    raise value
  File "/Library/Frameworks/Python.framework/Versions/3.7/lib/python3.7/site-packages/flask/app.py", line 1949, in full_dispatch_request
    rv = self.dispatch_request()
  File "/Library/Frameworks/Python.framework/Versions/3.7/lib/python3.7/site-packages/flask/app.py", line 1935, in dispatch_request
    return self.view_functions[rule.endpoint](**req.view_args)
  File "app.py", line 189, in create_venue_form
    form = VenueForm()
  File "/Library/Frameworks/Python.framework/Versions/3.7/lib/python3.7/site-packages/wtforms/form.py", line 212, in __call__
    return type.__call__(cls, *args, **kwargs)
  File "/Library/Frameworks/Python.framework/Versions/3.7/lib/python3.7/site-packages/flask_wtf/form.py", line 158, in __init__
    super(Form, self).__init__(*args, **kwargs)
  File "/Library/Frameworks/Python.framework/Versions/3.7/lib/python3.7/site-packages/flask_wtf/form.py", line 88, in __init__
    super(FlaskForm, self).__init__(formdata=formdata, **kwargs)
  File "/Library/Frameworks/Python.framework/Versions/3.7/lib/python3.7/site-packages/wtforms/form.py", line 278, in __init__
    self.process(formdata, obj, data=data, **kwargs)
  File "/Library/Frameworks/Python.framework/Versions/3.7/lib/python3.7/site-packages/wtforms/form.py", line 132, in process
    field.process(formdata)
  File "/Library/Frameworks/Python.framework/Versions/3.7/lib/python3.7/site-packages/wtforms/csrf/core.py", line 43, in process
    self.current_token = self.csrf_impl.generate_csrf_token(self)
  File "/Library/Frameworks/Python.framework/Versions/3.7/lib/python3.7/site-packages/flask_wtf/csrf.py", line 134, in generate_csrf_token
    token_key=self.meta.csrf_field_name
  File "/Library/Frameworks/Python.framework/Versions/3.7/lib/python3.7/site-packages/flask_wtf/csrf.py", line 35, in generate_csrf
    message='A secret key is required to use CSRF.'
  File "/Library/Frameworks/Python.framework/Versions/3.7/lib/python3.7/site-packages/flask_wtf/csrf.py", line 121, in _get_config
    raise KeyError(message)
KeyError: 'A secret key is required to use CSRF.'
2019-12-23 08:53:15,408 ERROR: Exception on /venues/create [GET] [in /Library/Frameworks/Python.framework/Versions/3.7/lib/python3.7/site-packages/flask/app.py:1891]
Traceback (most recent call last):
  File "/Library/Frameworks/Python.framework/Versions/3.7/lib/python3.7/site-packages/flask/app.py", line 2446, in wsgi_app
    response = self.full_dispatch_request()
  File "/Library/Frameworks/Python.framework/Versions/3.7/lib/python3.7/site-packages/flask/app.py", line 1951, in full_dispatch_request
    rv = self.handle_user_exception(e)
  File "/Library/Frameworks/Python.framework/Versions/3.7/lib/python3.7/site-packages/flask/app.py", line 1820, in handle_user_exception
    reraise(exc_type, exc_value, tb)
  File "/Library/Frameworks/Python.framework/Versions/3.7/lib/python3.7/site-packages/flask/_compat.py", line 39, in reraise
    raise value
  File "/Library/Frameworks/Python.framework/Versions/3.7/lib/python3.7/site-packages/flask/app.py", line 1949, in full_dispatch_request
    rv = self.dispatch_request()
  File "/Library/Frameworks/Python.framework/Versions/3.7/lib/python3.7/site-packages/flask/app.py", line 1935, in dispatch_request
    return self.view_functions[rule.endpoint](**req.view_args)
  File "app.py", line 189, in create_venue_form
    form = VenueForm()
  File "/Library/Frameworks/Python.framework/Versions/3.7/lib/python3.7/site-packages/wtforms/form.py", line 212, in __call__
    return type.__call__(cls, *args, **kwargs)
  File "/Library/Frameworks/Python.framework/Versions/3.7/lib/python3.7/site-packages/flask_wtf/form.py", line 158, in __init__
    super(Form, self).__init__(*args, **kwargs)
  File "/Library/Frameworks/Python.framework/Versions/3.7/lib/python3.7/site-packages/flask_wtf/form.py", line 88, in __init__
    super(FlaskForm, self).__init__(formdata=formdata, **kwargs)
  File "/Library/Frameworks/Python.framework/Versions/3.7/lib/python3.7/site-packages/wtforms/form.py", line 278, in __init__
    self.process(formdata, obj, data=data, **kwargs)
  File "/Library/Frameworks/Python.framework/Versions/3.7/lib/python3.7/site-packages/wtforms/form.py", line 132, in process
    field.process(formdata)
  File "/Library/Frameworks/Python.framework/Versions/3.7/lib/python3.7/site-packages/wtforms/csrf/core.py", line 43, in process
    self.current_token = self.csrf_impl.generate_csrf_token(self)
  File "/Library/Frameworks/Python.framework/Versions/3.7/lib/python3.7/site-packages/flask_wtf/csrf.py", line 134, in generate_csrf_token
    token_key=self.meta.csrf_field_name
  File "/Library/Frameworks/Python.framework/Versions/3.7/lib/python3.7/site-packages/flask_wtf/csrf.py", line 35, in generate_csrf
    message='A secret key is required to use CSRF.'
  File "/Library/Frameworks/Python.framework/Versions/3.7/lib/python3.7/site-packages/flask_wtf/csrf.py", line 121, in _get_config
    raise KeyError(message)
KeyError: 'A secret key is required to use CSRF.'
2019-12-23 08:53:20,986 INFO: errors [in app.py:586]
2019-12-23 08:53:34,307 ERROR: Exception on /venues/create [POST] [in /Library/Frameworks/Python.framework/Versions/3.7/lib/python3.7/site-packages/flask/app.py:1891]
Traceback (most recent call last):
  File "/Library/Frameworks/Python.framework/Versions/3.7/lib/python3.7/site-packages/flask/app.py", line 2446, in wsgi_app
    response = self.full_dispatch_request()
  File "/Library/Frameworks/Python.framework/Versions/3.7/lib/python3.7/site-packages/flask/app.py", line 1951, in full_dispatch_request
    rv = self.handle_user_exception(e)
  File "/Library/Frameworks/Python.framework/Versions/3.7/lib/python3.7/site-packages/flask/app.py", line 1820, in handle_user_exception
    reraise(exc_type, exc_value, tb)
  File "/Library/Frameworks/Python.framework/Versions/3.7/lib/python3.7/site-packages/flask/_compat.py", line 39, in reraise
    raise value
  File "/Library/Frameworks/Python.framework/Versions/3.7/lib/python3.7/site-packages/flask/app.py", line 1949, in full_dispatch_request
    rv = self.dispatch_request()
  File "/Library/Frameworks/Python.framework/Versions/3.7/lib/python3.7/site-packages/flask/app.py", line 1935, in dispatch_request
    return self.view_functions[rule.endpoint](**req.view_args)
  File "app.py", line 196, in create_venue_submission
    if form.validate():
  File "/Library/Frameworks/Python.framework/Versions/3.7/lib/python3.7/site-packages/wtforms/form.py", line 310, in validate
    return super(Form, self).validate(extra)
  File "/Library/Frameworks/Python.framework/Versions/3.7/lib/python3.7/site-packages/wtforms/form.py", line 152, in validate
    if not field.validate(self, extra):
  File "/Library/Frameworks/Python.framework/Versions/3.7/lib/python3.7/site-packages/wtforms/fields/core.py", line 206, in validate
    stop_validation = self._run_validation_chain(form, chain)
  File "/Library/Frameworks/Python.framework/Versions/3.7/lib/python3.7/site-packages/wtforms/fields/core.py", line 226, in _run_validation_chain
    validator(form, self)
TypeError: __init__() takes from 1 to 2 positional arguments but 3 were given
2019-12-23 09:02:40,407 INFO: errors [in app.py:586]
2019-12-23 09:03:58,201 INFO: errors [in app.py:586]
2019-12-23 09:06:24,532 INFO: errors [in app.py:586]
2019-12-23 09:09:21,512 INFO: errors [in app.py:586]
2019-12-23 09:10:03,431 INFO: errors [in app.py:586]
2019-12-23 09:10:03,935 INFO: errors [in /Users/amirtahmasbi/Documents/repo/udacity-fsnd/chapter2/final-project/fuyyer-app/app.py:586]
2019-12-23 09:10:30,042 INFO: errors [in /Users/amirtahmasbi/Documents/repo/udacity-fsnd/chapter2/final-project/fuyyer-app/app.py:587]
2019-12-23 09:11:57,460 INFO: errors [in /Users/amirtahmasbi/Documents/repo/udacity-fsnd/chapter2/final-project/fuyyer-app/app.py:588]
2019-12-23 09:12:18,918 INFO: errors [in app.py:588]
2019-12-23 09:12:19,437 INFO: errors [in /Users/amirtahmasbi/Documents/repo/udacity-fsnd/chapter2/final-project/fuyyer-app/app.py:588]
2019-12-23 09:14:19,496 INFO: errors [in /Users/amirtahmasbi/Documents/repo/udacity-fsnd/chapter2/final-project/fuyyer-app/app.py:589]
2019-12-23 09:14:24,874 INFO: errors [in app.py:589]
2019-12-23 09:14:25,388 INFO: errors [in /Users/amirtahmasbi/Documents/repo/udacity-fsnd/chapter2/final-project/fuyyer-app/app.py:589]
2019-12-23 09:23:10,344 INFO: errors [in /Users/amirtahmasbi/Documents/repo/udacity-fsnd/chapter2/final-project/fuyyer-app/app.py:589]
2019-12-23 09:23:20,133 INFO: errors [in /Users/amirtahmasbi/Documents/repo/udacity-fsnd/chapter2/final-project/fuyyer-app/app.py:589]
2019-12-23 09:23:40,604 INFO: errors [in app.py:589]
2019-12-23 09:23:41,098 INFO: errors [in /Users/amirtahmasbi/Documents/repo/udacity-fsnd/chapter2/final-project/fuyyer-app/app.py:589]
2019-12-23 09:28:59,395 INFO: errors [in app.py:589]
2019-12-23 09:28:59,887 INFO: errors [in /Users/amirtahmasbi/Documents/repo/udacity-fsnd/chapter2/final-project/fuyyer-app/app.py:589]
2019-12-23 09:29:24,990 INFO: errors [in /Users/amirtahmasbi/Documents/repo/udacity-fsnd/chapter2/final-project/fuyyer-app/app.py:589]
2019-12-23 09:29:44,968 INFO: errors [in /Users/amirtahmasbi/Documents/repo/udacity-fsnd/chapter2/final-project/fuyyer-app/app.py:590]
2019-12-23 09:29:48,206 INFO: errors [in app.py:590]
2019-12-23 09:29:48,691 INFO: errors [in /Users/amirtahmasbi/Documents/repo/udacity-fsnd/chapter2/final-project/fuyyer-app/app.py:590]
2019-12-23 09:31:22,181 INFO: errors [in /Users/amirtahmasbi/Documents/repo/udacity-fsnd/chapter2/final-project/fuyyer-app/app.py:591]
2019-12-23 09:31:25,445 INFO: errors [in app.py:591]
2019-12-23 09:31:25,943 INFO: errors [in /Users/amirtahmasbi/Documents/repo/udacity-fsnd/chapter2/final-project/fuyyer-app/app.py:591]
2019-12-23 13:49:39,944 INFO: errors [in app.py:591]
2019-12-23 13:49:40,447 INFO: errors [in /Users/amirtahmasbi/Documents/repo/udacity-fsnd/chapter2/final-project/fuyyer-app/app.py:591]
2019-12-23 13:56:26,941 INFO: errors [in app.py:591]
2019-12-23 13:56:27,462 INFO: errors [in /Users/amirtahmasbi/Documents/repo/udacity-fsnd/chapter2/final-project/fuyyer-app/app.py:591]
2019-12-23 13:58:26,724 INFO: errors [in /Users/amirtahmasbi/Documents/repo/udacity-fsnd/chapter2/final-project/fuyyer-app/app.py:591]
2019-12-23 13:59:33,773 INFO: errors [in /Users/amirtahmasbi/Documents/repo/udacity-fsnd/chapter2/final-project/fuyyer-app/app.py:591]
2019-12-23 14:00:55,124 INFO: errors [in /Users/amirtahmasbi/Documents/repo/udacity-fsnd/chapter2/final-project/fuyyer-app/app.py:591]
2019-12-23 14:01:11,591 INFO: errors [in app.py:591]
2019-12-23 14:01:12,078 INFO: errors [in /Users/amirtahmasbi/Documents/repo/udacity-fsnd/chapter2/final-project/fuyyer-app/app.py:591]
2019-12-23 14:02:44,735 INFO: errors [in /Users/amirtahmasbi/Documents/repo/udacity-fsnd/chapter2/final-project/fuyyer-app/app.py:591]
2019-12-23 14:02:47,017 INFO: errors [in app.py:591]
2019-12-23 14:02:47,531 INFO: errors [in /Users/amirtahmasbi/Documents/repo/udacity-fsnd/chapter2/final-project/fuyyer-app/app.py:591]
2019-12-23 14:04:26,257 INFO: errors [in /Users/amirtahmasbi/Documents/repo/udacity-fsnd/chapter2/final-project/fuyyer-app/app.py:591]
2019-12-23 14:04:29,051 INFO: errors [in app.py:591]
2019-12-23 14:04:29,525 INFO: errors [in /Users/amirtahmasbi/Documents/repo/udacity-fsnd/chapter2/final-project/fuyyer-app/app.py:591]
2019-12-23 14:05:09,062 INFO: errors [in /Users/amirtahmasbi/Documents/repo/udacity-fsnd/chapter2/final-project/fuyyer-app/app.py:591]
2019-12-23 14:06:48,760 INFO: errors [in app.py:591]
2019-12-23 14:06:49,266 INFO: errors [in /Users/amirtahmasbi/Documents/repo/udacity-fsnd/chapter2/final-project/fuyyer-app/app.py:591]
2019-12-23 14:07:22,528 INFO: errors [in app.py:590]
2019-12-23 14:07:23,025 INFO: errors [in /Users/amirtahmasbi/Documents/repo/udacity-fsnd/chapter2/final-project/fuyyer-app/app.py:590]
2019-12-23 14:08:54,181 INFO: errors [in app.py:591]
2019-12-23 14:08:54,692 INFO: errors [in /Users/amirtahmasbi/Documents/repo/udacity-fsnd/chapter2/final-project/fuyyer-app/app.py:591]
2019-12-23 14:09:56,037 INFO: errors [in /Users/amirtahmasbi/Documents/repo/udacity-fsnd/chapter2/final-project/fuyyer-app/app.py:591]
